<?xml version="1.0"?>
<robot name="BRT">
    <gazebo>
     <plugin name="gazebo_ros_control" filename="libgazebo_ros_control.so">
       <robotNamespace>/robot</robotNamespace>
       <robotSimType>gazebo_ros_control/DefaultRobotHWSim</robotSimType>
       <controlPeriod>0.001</controlPeriod>
       <legacyModeNS>true</legacyModeNS>
     </plugin>
   </gazebo>
  <link name="base_link">
        <visual>
            <geometry>
                <cylinder length="0.01" radius="0.053" />
            </geometry>
            <material name="black" />
            <origin rpy="0 0 0" xyz="0 0 0" />
        </visual>
        <inertial>
            <origin rpy="0 0 0" xyz="0 0 0" />
            <mass value="0.1"/>
            <inertia ixx="0.1" ixy="0.0" ixz="0.0" iyy="0.1" iyz="0.0" izz="0.1"/>
        </inertial>
    </link>

    <link name="braccio_base_link">
        <visual>
            <geometry>
                <mesh filename="package://BRT_Description/meshes/braccio_base.stl" scale="0.01 0.01 0.01" />
            </geometry>
            <material name="orange" />
            <origin rpy="0 0 3.1416" xyz="0 0.004 0" />
        </visual>
        <collision>
            <geometry>
                <mesh filename="package://BRT_Description/meshes/braccio_base.stl" scale="0.01 0.01 0.01" />
            </geometry>
            <origin rpy="0 0 0" xyz="0 0 0" />
        </collision>
        <inertial>
            <origin rpy="0 0 0" xyz="0 0.002 0.031" />
            <mass value="0.1"/>
            <inertia ixx="0.1" ixy="0.0" ixz="0.0" iyy="0.1" iyz="0.0" izz="0.1"/>
        </inertial>
    </link>

    <link name="shoulder_link">
        <visual>
            <geometry>
                <mesh filename="package://BRT_Description/meshes/braccio_shoulder.stl" scale="0.01 0.01 0.01" />
            </geometry>
            <material name="orange" />
            <origin rpy="0 0 0" xyz="-0.0045 0.0055 -0.026" />
        </visual>
        <collision>
            <geometry>
                <mesh filename="package://BRT_Description/meshes/braccio_shoulder.stl" scale="0.01 0.01 0.01" />
            </geometry>
            <origin rpy="0 0 0" xyz="-0.0045 0.0055 -0.026" />
        </collision>
        <inertial>
            <origin rpy="0 0 0" xyz="0 0.002 0.062" />
            <mass value="0.1"/>
            <inertia ixx="0.1" ixy="0.0" ixz="0.0" iyy="0.1" iyz="0.0" izz="0.1"/>
        </inertial>
    </link>

    <link name="elbow_link">
        <visual>
            <geometry>
                <mesh filename="package://BRT_Description/meshes/braccio_elbow.stl" scale="0.01 0.01 0.01" />
            </geometry>
            <material name="orange" />
            <origin rpy="0 0 0" xyz="-0.0045 0.005 -0.025" />
        </visual>
        <collision>
            <geometry>
                <mesh filename="package://BRT_Description/meshes/braccio_elbow.stl" scale="0.01 0.01 0.01" />
            </geometry>
            <origin rpy="0 0 0" xyz="-0.0045 0.005 -0.025" />
        </collision>
        <inertial>
            <origin rpy="0 0 0" xyz="0 0.002 0.062" />
            <mass value="0.1"/>
            <inertia ixx="0.1" ixy="0.0" ixz="0.0" iyy="0.1" iyz="0.0" izz="0.1"/>
        </inertial>
    </link>

    <link name="wrist_pitch_link">
        <visual>
            <geometry>
                <mesh filename="package://BRT_Description/meshes/braccio_wrist_pitch.stl" scale="0.01 0.01 0.01" />
            </geometry>
            <material name="orange" />
            <origin rpy="0 0 0" xyz="0.003 -0.0004 -0.024" />
        </visual>
        <collision>
            <geometry>
                <mesh filename="package://BRT_Description/meshes/braccio_wrist_pitch.stl" scale="0.01 0.01 0.01" />
            </geometry>
            <origin rpy="0 0 0" xyz="0.003 -0.0004 -0.024" />
        </collision>
        <inertial>
            <origin rpy="0 0 0" xyz="-0.004 -0.002 0.032" />
            <mass value="0.1"/>
            <inertia ixx="0.1" ixy="0.0" ixz="0.0" iyy="0.1" iyz="0.0" izz="0.1"/>
        </inertial>
    </link>

    <link name="wrist_roll_link">
        <visual>
            <geometry>
                <mesh filename="package://BRT_Description/meshes/braccio_wrist_roll.stl" scale="0.01 0.01 0.01" />
            </geometry>
            <material name="white" />
            <origin rpy="0 0 0" xyz="0.006 0 0.0" />
        </visual>
        <collision>
            <geometry>
                <mesh filename="package://BRT_Description/meshes/braccio_wrist_roll.stl" scale="0.01 0.01 0.01" />
            </geometry>
            <origin rpy="0 0 0" xyz="0.006 0 0.0" />
        </collision>
        <inertial>
            <origin rpy="0 0 0" xyz="-0.007 -0.002 0.018" />
            <mass value="0.1"/>
            <inertia ixx="0.1" ixy="0.0" ixz="0.0" iyy="0.1" iyz="0.0" izz="0.1"/>
        </inertial>
    </link>

    <link name="left_gripper_link">
        <visual>
            <geometry>
                <mesh filename="package://BRT_Description/meshes/braccio_left_gripper.stl" scale="0.01 0.01 0.01" />
            </geometry>
            <material name="white" />
            <origin rpy="0 1.5708 0" xyz="0 -0.012 0" />
        </visual>

        <inertial>
            <origin rpy="0 0 0" xyz="0.043 0.001 0.002" />
            <mass value="0.1" />
            <inertia ixx="0.000348958333333" ixy="0" ixz="0" iyy="0.000348958333333" iyz="0" izz="3.125e-05" />
        </inertial>

        <collision>
            <origin rpy="0 1.5708 0" xyz="0 -0.012 0" />
            <geometry>
                <mesh filename="package://BRT_Description/meshes/braccio_left_gripper.stl" scale="0.01 0.01 0.01" />
            </geometry>
        </collision>
    </link>
    <link name="right_gripper_link">
        <visual>
            <geometry>
                <mesh filename="package://BRT_Description/meshes/braccio_right_gripper.stl" scale="0.01 0.01 0.01" />
            </geometry>
            <material name="white" />
            <origin rpy="0 1.5708 0" xyz="0 -0.012 0.010" />
        </visual>

        <inertial>
            <origin rpy="0 0 0" xyz="0.043 0.001 0.002" />
            <mass value="0.1" />
            <inertia ixx="0.000348958333333" ixy="0" ixz="0" iyy="0.000348958333333" iyz="0" izz="3.125e-05" />
        </inertial>

        <collision>
            <origin rpy="0 1.5708 0" xyz="0 -0.012 0.010" />
            <geometry>
                <mesh filename="package://BRT_Description/meshes/braccio_right_gripper.stl" scale="0.01 0.01 0.01" />
            </geometry>
        </collision>
    </link>

    <joint name="base_joint" type="revolute">
        <axis xyz="0 0 -1" />
        <limit effort="1000.0" lower="0.0" upper="3.1416" velocity="1.0" />
        <origin rpy="0 0 0" xyz="0 0 0" />
        <parent link="base_link" />
        <child link="braccio_base_link" />
        <dynamics damping="0.1" friction="0.001" />
    </joint>

    <joint name="shoulder_joint" type="revolute">
        <axis xyz="1 0 0" />
        <limit effort="1000.0" lower="0.2618" upper="2.8798" velocity="1.0" />
        <origin rpy="-1.5708 0 0" xyz="0 -.002 0.072" />
        <parent link="braccio_base_link" />
        <child link="shoulder_link" />
        <dynamics damping="0.1" friction="0.001" />
    </joint>

    <joint name="elbow_joint" type="revolute">
        <axis xyz="1 0 0" />
        <limit effort="1000.0" lower="0" upper="3.1416" velocity="1.0" />
        <origin rpy="-1.5708 0 0" xyz="0 0 0.125" />
        <parent link="shoulder_link" />
        <child link="elbow_link" />
        <dynamics damping="0.1" friction="0.001" />
    </joint>

    <joint name="wrist_pitch_joint" type="revolute">
        <axis xyz="1 0 0" />
        <limit effort="1000.0" lower="0" upper="3.1416" velocity="1.0" />
        <origin rpy="-1.5708 0 0" xyz="0 0 0.125" />
        <parent link="elbow_link" />
        <child link="wrist_pitch_link" />
        <dynamics damping="0.1" friction="0.001" />
    </joint>

    <joint name="wrist_roll_joint" type="revolute">
        <axis xyz="0 0 -1" />
        <limit effort="1000.0" lower="0.0" upper="3.1416" velocity="1.0" />
        <origin rpy="0 0 1.5708" xyz="0 0.0 0.06" />
        <parent link="wrist_pitch_link" />
        <child link="wrist_roll_link" />
        <dynamics damping="0.1" friction="0.001" />
    </joint>

    <joint name="gripper_joint" type="revolute">
        <axis xyz="0 -1 0" />
        <limit effort="10.0" lower="0.1750" upper="1.2741" velocity="1.0" />
        <origin rpy="0 -0.2967 0" xyz="0.010 0 0.03" />
        <parent link="wrist_roll_link" />
        <child link="right_gripper_link" />
        <dynamics damping="0.1" friction="0.001" />
    </joint>
    <joint name="sub_gripper_joint" type="revolute">
        <axis xyz="0 1 0" />
        <limit effort="10.0" lower="0.1750" upper="1.2741" velocity="1.0" />
        <origin rpy="0 3.4383 0" xyz="-0.010 0 0.03" />
        <parent link="wrist_roll_link" />
        <child link="left_gripper_link" />
        <dynamics damping="0.1" friction="0.001" />
    </joint>

    <material name="orange">
        <color rgba="0.57 0.17 0.0 1" />
    </material>
    <material name="white">
        <color rgba="0.8 0.8 0.8 1.0" />
    </material>
    <material name="black">
        <color rgba="0 0 0 0.50" />
    </material>

  <transmission name="base_trasmision">
    <type>transmission_interface/SimpleTransmission</type>
    <joint name="base_joint">
      <hardwareInterface>hardware_interface/EffortJointInterface</hardwareInterface>
    </joint>
    <actuator name="base_motor">
      <hardwareInterface>hardware_interface/EffortJointInterface</hardwareInterface>
      <mechanicalReduction>1</mechanicalReduction>
    </actuator>
  </transmission>
  <transmission name="shoulder_trasmision">
    <type>transmission_interface/SimpleTransmission</type>
    <joint name="shoulder_joint">
      <hardwareInterface>hardware_interface/EffortJointInterface</hardwareInterface>
    </joint>
    <actuator name="shoulder_motor">
      <hardwareInterface>hardware_interface/EffortJointInterface</hardwareInterface>
      <mechanicalReduction>1</mechanicalReduction>
    </actuator>
  </transmission>
  <transmission name="elbow_trasmision">
    <type>transmission_interface/SimpleTransmission</type>
    <joint name="elbow_joint">
      <hardwareInterface>hardware_interface/EffortJointInterface</hardwareInterface>
    </joint>
    <actuator name="elbow_motor">
      <hardwareInterface>hardware_interface/EffortJointInterface</hardwareInterface>
      <mechanicalReduction>1</mechanicalReduction>
    </actuator>
  </transmission>
  <transmission name="wrist_pitch_trasmision">
    <type>transmission_interface/SimpleTransmission</type>
    <joint name="wrist_pitch_joint">
      <hardwareInterface>hardware_interface/EffortJointInterface</hardwareInterface>
    </joint>
    <actuator name="wrist_pitch_motor">
      <hardwareInterface>hardware_interface/EffortJointInterface</hardwareInterface>
      <mechanicalReduction>1</mechanicalReduction>
    </actuator>
  </transmission>
  <transmission name="wrist_roll_trasmision">
    <type>transmission_interface/SimpleTransmission</type>
    <joint name="wrist_roll_joint">
      <hardwareInterface>hardware_interface/EffortJointInterface</hardwareInterface>
    </joint>
    <actuator name="wrist_roll_motor">
      <hardwareInterface>hardware_interface/EffortJointInterface</hardwareInterface>
      <mechanicalReduction>1</mechanicalReduction>
    </actuator>
  </transmission>
  <transmission name="gripper_trasmision">
    <type>transmission_interface/SimpleTransmission</type>
    <joint name="gripper_joint">
      <hardwareInterface>hardware_interface/EffortJointInterface</hardwareInterface>
    </joint>
    <actuator name="gripper_motor">
      <hardwareInterface>hardware_interface/EffortJointInterface</hardwareInterface>
      <mechanicalReduction>1</mechanicalReduction>
    </actuator>
  </transmission>
  <transmission name="sub_gripper_trasmision">
    <type>transmission_interface/SimpleTransmission</type>
    <joint name="sub_gripper_joint">
      <hardwareInterface>hardware_interface/EffortJointInterface</hardwareInterface>
    </joint>
    <actuator name="sub_gripper_motor">
      <hardwareInterface>hardware_interface/EffortJointInterface</hardwareInterface>
      <mechanicalReduction>1</mechanicalReduction>
    </actuator>
  </transmission>
   <gazebo reference="braccio_base_link">
    <material>Gazebo/Orange</material>
  </gazebo>
  <gazebo reference="shoulder_link">
    <material>Gazebo/Orange</material>
  </gazebo>
  <gazebo reference="elbow_link">
    <material>Gazebo/Orange</material>
  </gazebo>
  <gazebo reference="wrist_pitch_link">
    <material>Gazebo/Orange</material>
  </gazebo>
  <gazebo reference="wrist_roll_link">
    <material>Gazebo/Orange</material>
  </gazebo>
  <gazebo reference="right_gripper_link">
    <material>Gazebo/White</material>
  </gazebo>
  <gazebo reference="left_gripper_link">
    <material>Gazebo/White</material>
  </gazebo>
  <gazebo reference="base_link">
    <material>Gazebo/Orange</material>
  </gazebo>
  <link name="world"/>
  <joint name="world_joint" type="fixed">
    <parent link="world"/>
    <child link="base_link"/>
    <origin rpy="0.0 0.0 0.0" xyz="0.0 0.0 0.0"/>
  </joint>
</robot>
