<?xml version="1.0"?>
<robot name="braccio">
     <gazebo>
     <plugin name="gazebo_ros_control" filename="libgazebo_ros_control.so">
       <robotNamespace>/robot</robotNamespace>
       <controlPeriod>0.001</controlPeriod>
       <legacyModeNS>true</legacyModeNS>
     </plugin>
   </gazebo>
    
    <!--<gazebo>
       <plugin filename="libroboticsgroup_gazebo_mimic_joint_plugin.so" name="sub_gripper">
        <joint>gripper_joint</joint>
        <mimicJoint>sub_gripper_joint</mimicJoint>
        <multiplier>1</multiplier>
      </plugin> 
    </gazebo>-->
    <!-- Color de materiales -->
    <material name="orange">
        <color rgba="0.57 0.17 0.0 1" />
    </material>
    <material name="white">
        <color rgba="0.8 0.8 0.8 1.0" />
    </material>
    <material name="black">
        <color rgba="0 0 0 0.50" />
    </material>

    <!--Mascaras para partes del robot-->
    <link name="base_link">
        <visual>
            <geometry>
                <cylinder length="0.01" radius=".053" />
            </geometry>
            <material name="black" />
            <origin rpy="0 0 0" xyz="0 0 0" />
        </visual>
        <inertial>
            <origin rpy="0 0 0" xyz="0 0 0" />
            <mass value="0.1" />
            <inertia ixx="0.1" ixy="0.0" ixz="0.0" iyy="0.1" iyz="0.0" izz="0.1"/>
        </inertial>
    </link>

    <link name="braccio_base_link">
        <visual>
            <geometry>
                <mesh filename="package://BRT_Description/meshes/braccio_base.stl" scale="0.01 0.01 0.01" />
            </geometry>
            <material name="orange" />
            <origin rpy="0 0 3.1416" xyz="0 0.004 0" />
        </visual>
        <collision>
            <geometry>
                <mesh filename="package://BRT_Description/meshes/braccio_base.stl" scale="0.01 0.01 0.01" />
            </geometry>
            <origin rpy="0 0 0" xyz="0 0.002 0.031" />
        </collision>
        <inertial>
            <origin rpy="0 0 0" xyz="0 0.002 0.031" />
            <mass value="0.16" />
            <inertia ixx="3.54" ixy="0.0" ixz="0.003" iyy="3.5" iyz="-0.01" izz="0.67"/>
        </inertial>
    </link>

    <link name="shoulder_link">
        <visual>
            <geometry>
                <mesh filename="package://BRT_Description/meshes/braccio_shoulder.stl" scale="0.009 0.01 0.01" />
            </geometry>
            <material name="orange" />
            <origin rpy="0 0 0" xyz="-0.0045 0.0055 -0.026" />
        </visual>
        <collision>
            <geometry>
                <mesh filename="package://BRT_Description/meshes/braccio_shoulder.stl" scale="0.009 0.01 0.01" />
            </geometry>
            <origin rpy="0 0 0" xyz="-0.0045 0.0055 -0.026" />
        </collision>
        <inertial>
            <origin rpy="0 0 0" xyz="0 0.002 0.062" />
            <mass value="0.16" />
            <inertia ixx="3.54" ixy="0.0" ixz="0.019" iyy="3.5" iyz="-0.008" izz="0.69"/>
        </inertial>
    </link>

     <link name="elbow_link">
        <visual>
            <geometry>
                <mesh filename="package://BRT_Description/meshes/braccio_elbow.stl" scale="0.01 0.01 0.01" />
            </geometry>
            <material name="orange" />
            <origin rpy="0 0 0" xyz="-0.0045 0.005 -0.025" />
        </visual>
        <collision>
            <geometry>
                <mesh filename="package://BRT_Description/meshes/braccio_elbow.stl" scale="0.01 0.01 0.01" />
            </geometry>
            <origin rpy="0 0 0" xyz="-0.0045 0.005 -0.025" />
        </collision>
        <inertial>
            <origin rpy="0 0 0" xyz="0 0.002 0.062" />
            <mass value="0.169" />
            <inertia ixx="10.74" ixy="0.0007" ixz="0.16068" iyy="13.58" iyz="0.019" izz="14.25"/>
        </inertial>
    </link>

     <link name="wrist_pitch_link">
        <visual>
            <geometry>
                <mesh filename="package://BRT_Description/meshes/braccio_wrist_pitch.stl" scale="0.01 0.01 0.01" />
            </geometry>
            <material name="orange" />
            <origin rpy="0 0 0" xyz="0.003 -0.0004 -0.024" />
        </visual>
        <collision>
            <geometry>
                 <mesh filename="package://BRT_Description/meshes/braccio_wrist_pitch.stl" scale="0.01 0.01 0.01" />
            </geometry>
            <origin rpy="0 0 0" xyz="0.003 -0.0004 -0.024" />
        </collision>
        <inertial>-->
           <origin rpy="0 0 0" xyz="-0.004 -0.002 0.032" />
            <mass value="0.062" />
            <inertia ixx="5.18" ixy="-0.0025" ixz="-0.04" iyy="0.7782" iyz="-0.00018" izz="4.125" />
        </inertial>
    </link>

    <link name="wrist_roll_link">
        <visual>
            <geometry>
                <mesh filename="package://BRT_Description/meshes/braccio_wrist_roll.stl" scale="0.01 0.01 0.01" />
            </geometry>
            <material name="white" />
            <origin rpy="0 0 0" xyz="0.006 0 0.0" />
        </visual>
        <collision>
            <geometry>
                <mesh filename="package://BRT_Description/meshes/braccio_wrist_roll.stl" scale="0.01 0.01 0.01" />
            </geometry>
            <origin rpy="0 0 0" xyz="0.006 0 0.0" />
        </collision>
        <inertial>
            <origin rpy="0 0 0" xyz="-0.007 -0.002 0.018" />
            <mass value="0.022" />
            <inertia ixx="0.5" ixy="-0.0002" ixz="-0.0003" iyy="1.108" iyz="0.0691" izz="0.66" />
        </inertial>
    </link>

    <link name="left_gripper_link">
        <visual>
            <geometry>
                <mesh filename="package://BRT_Description/meshes/braccio_left_gripper.stl" scale="0.01 0.01 0.01" />
            </geometry>
            <material name="white" />
            <origin rpy="0 1.5708 0" xyz="0 -0.012 0" />
        </visual>

        <inertial>
            <origin rpy="0 0 0" xyz="0.043 0.001 0.002" />
            <mass value="0.002" />
            <inertia ixx="0.000176" ixy="0" ixz="-0.000050" iyy="0.00179" iyz="0" izz="0.000033" />
        </inertial>

        <collision>
            <origin rpy="0 1.5708 0" xyz="0 -0.012 0" />
            <geometry>
                <mesh filename="package://BRT_Description/meshes/braccio_left_gripper.stl" scale="0.01 0.01 0.01" />
            </geometry>
        </collision>
    </link>
    <link name="right_gripper_link">
        <visual>
            <geometry>
                <mesh filename="package://BRT_Description/meshes/braccio_right_gripper.stl" scale="0.01 0.01 0.01" />
            </geometry>
            <material name="white" />
            <origin rpy="0 1.5708 0" xyz="0 -0.012 0.010" />
        </visual>

        <inertial>
            <origin rpy="0 0 0" xyz="0.043 0.001 0.002" />
            <mass value="0.002" />
            <inertia ixx="0.000176" ixy="0" ixz="-0.000050" iyy="0.00179" iyz="0" izz="0.000033" />
        </inertial>

        <collision>
            <origin rpy="0 1.5708 0" xyz="0 -0.012 0.010" />
            <geometry>
                <mesh filename="package://BRT_Description/meshes/braccio_right_gripper.stl" scale="0.01 0.01 0.01" />
            </geometry>
        </collision>
    </link>

    <!--Articulaciones del robot-->

    <joint name="base_joint" type="revolute">
        <axis xyz="0 0 -1" />
        <limit effort="1000.0" lower="0.0" upper="3.1416" velocity="1.0" />
        <origin rpy="0 0 0" xyz="0 0 0" />
        <parent link="base_link" />
        <child link="braccio_base_link" />
        <dynamics damping="0.1" friction="0.001" />
    </joint>
    
    <transmission name="base_trasmision">
        <type>transmission_interface/SimpleTransmission</type>
        <joint name="base_joint">
            <hardwareInterface>
                 hardware_interface/EffortJointInterface
            </hardwareInterface>
        </joint>
        <actuator name="base_motor">
         <hardwareInterface> hardware_interface/EffortJointInterface</hardwareInterface>
         <mechanicalReduction>1</mechanicalReduction>
        </actuator>
    </transmission>

    <joint name="shoulder_joint" type="revolute">
        <axis xyz="1 0 0" />
        <limit effort="1000.0" lower="0.2" upper="2.8" velocity="1.0" />
        <origin rpy="-1.5708 0 0" xyz="0 -0.002 0.072" />
        <parent link="braccio_base_link" />
        <child link="shoulder_link" />
        <dynamics damping="0.1" friction="0.001" />
    </joint>
    <transmission name="shoulder_trasmision">
        <type>transmission_interface/SimpleTransmission</type>
        <joint name="shoulder_joint">
            <hardwareInterface>
                 hardware_interface/EffortJointInterface
	    </hardwareInterface>
        </joint>
        <actuator name="shoulder_motor">
         <hardwareInterface> hardware_interface/EffortJointInterface</hardwareInterface>
         <mechanicalReduction>1</mechanicalReduction>
        </actuator>
    </transmission>

    <joint name="elbow_joint" type="revolute">
        <axis xyz="1 0 0" />
        <limit effort="1000.0" lower="0.0" upper="3.1416" velocity="1.0" />
        <origin rpy="-1.5708 0 0" xyz="0 0 0.125" />
        <parent link="shoulder_link" />
        <child link="elbow_link" />
        <dynamics damping="0.1" friction="0.001" />
    </joint>
    <transmission name="elbow_trasmision">
        <type>transmission_interface/SimpleTransmission</type>
        <joint name="elbow_joint">
            <hardwareInterface>
                 hardware_interface/EffortJointInterface
            </hardwareInterface>
        </joint>
        <actuator name="elbow_motor">
        <hardwareInterface> hardware_interface/EffortJointInterface</hardwareInterface>
        <mechanicalReduction>1</mechanicalReduction>
        </actuator>
    </transmission>

    <joint name="wrist_pitch_joint" type="revolute">
        <axis xyz="1 0 0" />
        <limit effort="1000.0" lower="0.0" upper="3.1416" velocity="1.0" />
        <origin rpy="-1.5708 0 0" xyz="0 0 0.125" />
        <parent link="elbow_link" />
        <child link="wrist_pitch_link" />
        <dynamics damping="0.1" friction="0.001" />
    </joint>
    <transmission name="wrist_pitch_trasmision">
        <type>transmission_interface/SimpleTransmission</type>
        <joint name="wrist_pitch_joint">
            <hardwareInterface>
                hardware_interface/EffortJointInterface
            </hardwareInterface>
        </joint>
        <actuator name="wrist_pitch_motor">
        <hardwareInterface> hardware_interface/EffortJointInterface</hardwareInterface>
        <mechanicalReduction>1</mechanicalReduction>
        </actuator>
    </transmission>

   <joint name="wrist_roll_joint" type="revolute">
        <axis xyz="0 0 -1" />
        <limit effort="1000.0" lower="0.0" upper="3.1416" velocity="1.0" />
        <origin rpy="0 0 1.5708" xyz="0 0.0 0.06" />
        <parent link="wrist_pitch_link" />
        <child link="wrist_roll_link" />
        <dynamics damping="0.1" friction="0.001" />
    </joint>
    <transmission name="wrist_roll_trasmision">
        <type>transmission_interface/SimpleTransmission</type>
        <joint name="wrist_roll_joint">
            <hardwareInterface>
                hardware_interface/EffortJointInterface
            </hardwareInterface>
        </joint>
        <actuator name="wrist_roll_motor">
        <hardwareInterface> hardware_interface/EffortJointInterface</hardwareInterface>
        <mechanicalReduction>1</mechanicalReduction>
        </actuator>
    </transmission>

     <joint name="gripper_joint" type="revolute">
        <axis xyz="0 -1 0" />
        <limit effort="10.0" lower="0.1750" upper="1.2741" velocity="1.0" />
        <origin rpy="0 -0.2967 0" xyz="0.010 0 0.03" />
        <parent link="wrist_roll_link" />
        <child link="right_gripper_link" />
       <dynamics damping="0.1" friction="0.001" />
    </joint>
    <transmission name="gripper_trasmision">
        <type>transmission_interface/SimpleTransmission</type>
        <joint name="gripper_joint">
            <hardwareInterface>
                 hardware_interface/PositionJointInterface
            </hardwareInterface>
        </joint>
        <actuator name="gripper_motor">
        <mechanicalReduction>1</mechanicalReduction>
        <hardwareInterface>hardware_interface/PositionJointInterface</hardwareInterface>
        </actuator>
    </transmission>
    

    <joint name="sub_gripper_joint" type="revolute">
        <axis xyz="0 1 0" />
        <limit effort="10.0" lower="0.1750" upper="1.2741" velocity="1.0" />
        <origin rpy="0 3.4383 0" xyz="-0.010 0 0.03" />
        <parent link="wrist_roll_link" />
        <child link="left_gripper_link" />
    </joint>
    <transmission name="sub_gripper_trasmision">
        <type>transmission_interface/SimpleTransmission</type>
        <joint name="sub_gripper_joint">
            <hardwareInterface>
                hardware_interface/PositionJointInterface
            </hardwareInterface>
        </joint>
        <actuator name="sub_gripper_motor">
        <mechanicalReduction>1</mechanicalReduction>
        <hardwareInterface>hardware_interface/PositionJointInterface</hardwareInterface>
        </actuator>
    </transmission> 
    
    <link name="world"/>
    <joint name="world_joint" type="fixed">
        <parent link="world"/>
        <child link="base_link"/>
        <origin rpy="0.0 0.0 0.0" xyz="0.0 0.0 0.0"/>
    </joint>
    
    <gazebo reference="base_link">
        <mu1>1</mu1>
        <mu2>1</mu2>
        <selfCollide>true</selfCollide>
        <material>Gazebo/Orange</material>
    </gazebo>

  <gazebo reference="braccio_base_link">
    <material>Gazebo/Orange</material>
    <mu1>1</mu1>
    <mu2>1</mu2>
    <selfCollide>true</selfCollide>
  </gazebo>
  <gazebo reference="shoulder_link">
    <material>Gazebo/Orange</material>
    <mu1>1</mu1>
    <mu2>1</mu2>
    <selfCollide>true</selfCollide>
  </gazebo>
  <gazebo reference="elbow_link">
    <material>Gazebo/Orange</material>
    <mu1>1</mu1>
    <mu2>1</mu2>
    <selfCollide>true</selfCollide>
  </gazebo>
  <gazebo reference="wrist_pitch_link">
    <material>Gazebo/Orange</material>
    <mu1>1</mu1>
    <mu2>1</mu2>
    <selfCollide>true</selfCollide>
  </gazebo>
  <gazebo reference="wrist_roll_link">
    <material>Gazebo/White</material>
    <mu1>1</mu1>
    <mu2>1</mu2>
    <selfCollide>true</selfCollide>
  </gazebo>
  <gazebo reference="right_gripper_link">
    <material>Gazebo/White</material>
    <mu1>0.5</mu1>
    <mu2>0.5</mu2>
    <kp>500000.0</kp>
    <kd>10.0</kd>
    <minDepth>0.001</minDepth>
    <maxVel>0.1</maxVel>
    <fdir1>1 0 0</fdir1>
  </gazebo>
  <gazebo reference="left_gripper_link">
    <material>Gazebo/White</material>
    <mu1>0.5</mu1>
    <mu2>0.5</mu2>
    <kp>500000.0</kp>
    <kd>10.0</kd>
    <minDepth>0.001</minDepth>
    <maxVel>0.1</maxVel>
    <fdir1>1 0 0</fdir1>
  </gazebo>
  <gazebo reference="gripper_joint">
        <implicitSpringDamper>1</implicitSpringDamper>
    </gazebo>
  <gazebo reference="sub_gripper_joint">
     <implicitSpringDamper>1</implicitSpringDamper>
  </gazebo>
 <!--INICIO DE RGB CAMERA-->
    <joint name="table_joint" type="fixed">
        <parent link="world"/>
        <child link="camera_link"/> <!--0 80 18 cm-->
        <origin rpy="0 0 -1.57" xyz="0.0 0.45 0.3"/>
    </joint>

    <link name="camera_link">
        <collision>
        <origin xyz="0 0 0" rpy="0 0 0"/>
        <geometry>
            <box size="0.03 0.06 0.03"/>
        </geometry>
        </collision>

        <visual>
        <origin xyz="0 0 0" rpy="0 0 0"/>
        <geometry>
            <box size="0.03 0.06 0.03"/>
        </geometry>
        <material name="black"/>
        </visual>
        <inertial>
        <mass value="1e-5" />
        <origin xyz="0 0 0" rpy="0 0 0"/>
        <inertia ixx="1e-6" ixy="0" ixz="0" iyy="1e-6" iyz="0" izz="1e-6" />
        </inertial>
    </link>

    <joint name="camera_rgb_joint" type="fixed">
        <origin xyz="0.003 0.011 0.009" rpy="0 0 0"/>
        <parent link="camera_link"/>
        <child link="camera_rgb_frame"/>
    </joint>
    <link name="camera_rgb_frame"/>

    <joint name="camera_rgb_optical_joint" type="fixed">
        <origin xyz="0 0 0" rpy="-1.57 0 -1.57"/>
        <parent link="camera_rgb_frame"/>
        <child link="camera_rgb_optical_frame"/>
    </joint>
    <link name="camera_rgb_optical_frame"/>

    <gazebo reference="camera_link">
        <sensor type="camera" name="usb_camera">
        <update_rate>30.0</update_rate>
        <camera name="usb">
            <horizontal_fov>1.3962634</horizontal_fov>
            <image>
            <width>800</width>
            <height>800</height>
            <format>R8G8B8</format>
            </image>
            <clip>
            <near>0.02</near>
            <far>300</far>
            </clip>
            <noise>
            <type>gaussian</type>
            <!-- Noise is sampled independently per pixel on each frame. That pixel's noise value is added to each of its color channels, which at that point lie in the range [0,1]. -->
            <mean>0.0</mean>
            <stddev>0.007</stddev>
            </noise>
        </camera>
        <plugin name="camera_controller" filename="libgazebo_ros_camera.so">
            <alwaysOn>true</alwaysOn>
            <updateRate>30.0</updateRate>
            <cameraName>usb_camera</cameraName>
            <imageTopicName>image_raw</imageTopicName>
            <cameraInfoTopicName>camera_info</cameraInfoTopicName>
            <frameName>camera_rgb_optical_frame</frameName>
            <hackBaseline>0.07</hackBaseline>
            <distortionK1>0.0</distortionK1>
            <distortionK2>0.0</distortionK2>
            <distortionK3>0.0</distortionK3>
            <distortionT1>0.0</distortionT1>
            <distortionT2>0.0</distortionT2>
        </plugin>
        </sensor>
    </gazebo>

    <gazebo reference="camera_link">
        <material>Gazebo/Black</material>
    </gazebo>



</robot>
